Workbook

Sheet Dashboard
B2: RawTalent · Project Management Tracker
B3: Casual Staffing Made Easy — Operational Initiatives, Owners & Progress
B4: Live dashboard — auto-calculates from the Initiatives tab. Update Initiatives, and this refreshes.
B6: TOTAL PROJECTS | D6: IN PROGRESS | F6: COMPLETE | H6: BLOCKED / AT RISK | J6: % COMPLETE
B7: =COUNTA(Project!B5:B201) -> 29 | D7: =COUNTIF(Project!G5:G201,"In Progress") -> 8 | F7: =COUNTIF(Project!G5:G201,"Complete") -> 0 | H7: =COUNTIF(Project!G5:G201,"Blocked")+COUNTIF(Project!G5:G201,"At Risk") -> 0 | J7: =IFERROR(COUNTIF(Project!G5:G201,"Complete")/COUNTA(Project!B5:B201),0) -> 0
B11: STATUS BREAKDOWN
B12: Status | C12: Count
B13: Not Started | C13: =COUNTIF(Project!G5:G201,"Not Started") -> 21
B14: In Progress | C14: =COUNTIF(Project!G5:G201,"In Progress") -> 8
B15: Blocked | C15: =COUNTIF(Project!G5:G201,"Blocked") -> 0
B16: At Risk | C16: =COUNTIF(Project!G5:G201,"At Risk") -> 0
B17: Complete | C17: =COUNTIF(Project!G5:G201,"Complete") -> 0
B18: On Hold | C18: =COUNTIF(Project!G5:G201,"On Hold") -> 0
B21: WORKLOAD BY OWNER
B22: Owner | C22: Open Items
B23: Liam | C23: =COUNTIFS(Project!F5:F201,"*Liam*",Project!G5:G201,"<>Complete") -> 5
B24: Jane | C24: =COUNTIFS(Project!F5:F201,"*Jane*",Project!G5:G201,"<>Complete") -> 4
B25: Adrian | C25: =COUNTIFS(Project!F5:F201,"*Adrian*",Project!G5:G201,"<>Complete") -> 0
B26: Lorie | C26: =COUNTIFS(Project!F5:F201,"*Lorie*",Project!G5:G201,"<>Complete") -> 2
B27: Sophia | C27: =COUNTIFS(Project!F5:F201,"*Sophia*",Project!G5:G201,"<>Complete") -> 10
B28: Joy | C28: =COUNTIFS(Project!F5:F201,"*Joy*",Project!G5:G201,"<>Complete") -> 11
B29: Raj/Prince | C29: =COUNTIFS(Project!F5:F201,"*Raj/Prince*",Project!G5:G201,"<>Complete") -> 2

Sheet Project
B2: RawTalent · Project Tracker
B3: Add one row per initiative. Fill every column. Update Status + % Complete + Last Update weekly (Mondays). Overdue dates auto-flag red.
B4: ID | C4: Project | D4: Description / Context | E4: Category | F4: Owner | G4: Status | H4: Priority | I4: Date Started | J4: Target Date | K4: Days Open | L4: Days to Due | M4: % Complete | N4: Success Metric (how we know it worked) | O4: Data Source | P4: Blockers / Risk | Q4: Last Update | R4: Updated On
B5: RT-01 | C5: Reclassify cancellation data & restate true fill rate | D5: Stop logging last-minute centre cancellations as "client cancelled" when actually unfilled. Restate ~72% true SA fill rate internally and to Edge. Train team on new rule. | E5: Data & Reporting | F5: Jane | G5: In Progress | H5: P1 | I5: 46175 | J5: 46189 | K5: =IF(I5="","",IF(G5="Complete",R5-I5,TODAY()-I5)) -> 7 | L5: =IF(J5="","",IF(G5="Complete","Done",J5-TODAY())) -> 7 | M5: =IFERROR(IF(I5="","",MIN(1,MAX(0,(TODAY()-I5)/(J5-I5)))),"") -> 0.5 | N5: All cancellations correctly classified for 4 consecutive weeks; one true fill-rate number reported | O5: Booking platform / Monthly Report | Q5: Definitions drafted; team briefing pending | R5: 46180
B6: RT-02 | C6: Close SA pay gap at worst-fill centres | D6: Raw Talent pays ~$42/hr vs competitor ~$46/hr; educators take higher-paid shift. Re-price Brahma Lodge (59.5%), Flagstaff Hill (62.4%), Angle Vale Merlot, Gawler East. Model profitability vs Edge charge rates first. | E6: Operations | F6: Liam | G6: Not Started | H6: P1 | J6: 46203 | K6: =IF(I6="","",IF(G6="Complete",R6-I6,TODAY()-I6)) | L6: =IF(J6="","",IF(G6="Complete","Done",J6-TODAY())) -> 21 | M6: =IFERROR(IF(I6="","",MIN(1,MAX(0,(TODAY()-I6)/(J6-I6)))),"") | N6: Top-4 SA centres clear 90% fill within 6 weeks of re-pricing | O6: SA Educator Engagement Report | P6: Need per-centre charge-rate vs pay-rate model | Q6: Awaiting profitability model from Joy | R6: 46180
B7: RT-03 | C7: Fix app geofencing / notification bug (hidden shifts) | D7: Compliant, in-radius SA educators not seeing live bookings; admin must assign manually. Escalate to dev (Prince/Raj) with screenshots, timestamps, booking IDs + same-time speed test. Interim: paid SMS alerts. | E7: Technology | F7: Raj/Prince | G7: In Progress | H7: P1 | I7: 46176 | J7: 46193 | K7: =IF(I7="","",IF(G7="Complete",R7-I7,TODAY()-I7)) -> 6 | L7: =IF(J7="","",IF(G7="Complete","Done",J7-TODAY())) -> 11 | M7: =IFERROR(IF(I7="","",MIN(1,MAX(0,(TODAY()-I7)/(J7-I7)))),"") -> 0.35294118 | N7: In-radius compliant educators reliably receive & see all eligible shifts | O7: App / Portal admin logs | P7: Needs reproducible evidence pack | Q7: Evidence being collected by Lorie | R7: 46180
B8: RT-04 | C8: Daily SA fill war-room | D8: Daily triage of top-volume Edge centres (Royal Park, Brahma Lodge, Virginia, Elizabeth Park): favourites push, availability checks, backup-pool activation before centres cancel. | E8: Operations | F8: Lorie | G8: Not Started | H8: P1 | J8: 46186 | K8: =IF(I8="","",IF(G8="Complete",R8-I8,TODAY()-I8)) | L8: =IF(J8="","",IF(G8="Complete","Done",J8-TODAY())) -> 4 | M8: =IFERROR(IF(I8="","",MIN(1,MAX(0,(TODAY()-I8)/(J8-I8)))),"") | N8: Weekly SA fill rate trending to 90%+ | O8: Daily booking report | Q8: Setting up 8am stand-up | R8: 46180
B9: RT-05 | C9: SA educator engagement & appreciation drive | D9: Call active/dormant SA educators (4-6pm best contact) to surface app issues & retain. Educator appreciation certificates hand-delivered on centre visits. Grow finite Adelaide pool. | E9: Supply / Educators | F9: Lorie | G9: In Progress | H9: P1 | I9: 46177 | J9: 46200 | K9: =IF(I9="","",IF(G9="Complete",R9-I9,TODAY()-I9)) -> 5 | L9: =IF(J9="","",IF(G9="Complete","Done",J9-TODAY())) -> 18 | M9: =IFERROR(IF(I9="","",MIN(1,MAX(0,(TODAY()-I9)/(J9-I9)))),"") -> 0.2173913 | N9: 166 SA educators retained/grown; first-shift conversion improved | O9: SA Educator Engagement Report | Q9: 10-15 appreciation certs in production | R9: 46180
B10: RT-06 | C10: Liam SA centre & educator discovery calls | D10: Visit/record Edge centres + call SA educators in 3 segments (active / declining / lapsed) to learn why they drift to Entrée, what Entrée does well, and what to fix. | E10: Client Relationships | F10: Liam | G10: In Progress | H10: P1 | I10: 46178 | J10: 46207 | K10: =IF(I10="","",IF(G10="Complete",R10-I10,TODAY()-I10)) -> 4 | L10: =IF(J10="","",IF(G10="Complete","Done",J10-TODAY())) -> 25 | M10: =IFERROR(IF(I10="","",MIN(1,MAX(0,(TODAY()-I10)/(J10-I10)))),"") -> 0.13793103 | N10: Documented insight pack: why Edge leaves, Entrée strengths, fix list | O10: Recorded calls (AI-analysed) | Q10: Centre visit list being built with Jane | R10: 46180
B11: RT-07 | C11: Rebuild onboarding funnel (lift ~10% activation) | D11: Move qualifying earlier (phone screen + references + video before portal). Centre-callback references with weighted pass/fail (>=70%). Video-interview prep explainer to cut apprehension. Tighten ad targeting. | E11: Onboarding (Applicant) | F11: Jane | G11: Not Started | H11: P2 | J11: 46249 | K11: =IF(I11="","",IF(G11="Complete",R11-I11,TODAY()-I11)) | L11: =IF(J11="","",IF(G11="Complete","Done",J11-TODAY())) -> 67 | M11: =IFERROR(IF(I11="","",MIN(1,MAX(0,(TODAY()-I11)/(J11-I11)))),"") | N11: Activation rate lifted from ~10% toward 25%+; SA prioritised | O11: Onboarding funnel report | P11: Reference form rewrite + SOPs needed | Q11: New reference call-flow in design | R11: 46180
B12: RT-08 | C12: Redesign client onboarding (tech + nurture sequences) | D12: Rework how new centres are onboarded — landing pages, email nurture, SOPs, portal touchpoints. | E12: Onboarding (Client) | F12: Jane | G12: Not Started | H12: P2 | J12: 46218 | K12: =IF(I12="","",IF(G12="Complete",R12-I12,TODAY()-I12)) | L12: =IF(J12="","",IF(G12="Complete","Done",J12-TODAY())) -> 36 | M12: =IFERROR(IF(I12="","",MIN(1,MAX(0,(TODAY()-I12)/(J12-I12)))),"") | N12: New client onboarding live & tested with 3 centres | O12: CRM / dev board | Q12: Scope to be confirmed with Liam | R12: 46180
B13: RT-09 | C13: Hire local SA Account Manager / Workforce Partner | D13: On-the-ground Adelaide relationship manager (centre visits, feature adoption, retention) while offshore team runs transactional bookings. Trial with retention KPIs. | E13: People & Org | F13: Liam | G13: Not Started | H13: P2 | J13: 46235 | K13: =IF(I13="","",IF(G13="Complete",R13-I13,TODAY()-I13)) | L13: =IF(J13="","",IF(G13="Complete","Done",J13-TODAY())) -> 53 | M13: =IFERROR(IF(I13="","",MIN(1,MAX(0,(TODAY()-I13)/(J13-I13)))),"") | N13: AM in seat; SA centre retention & favourites up | O13: HR / hiring pipeline | Q13: Role + KPIs to be defined (one-pager) | R13: 46180
B14: RT-10 | C14: Two-tier pricing pilot (vs Talent Now Casual Connect) | D14: Add a booking-fee-only tier alongside full-service; prepare Worker Retention Payment-eligible messaging before scheme expiry 30 Nov 2026. | E14: Operations | F14: Liam | G14: Not Started | H14: P2 | J14: 46280 | K14: =IF(I14="","",IF(G14="Complete",R14-I14,TODAY()-I14)) | L14: =IF(J14="","",IF(G14="Complete","Done",J14-TODAY())) -> 98 | M14: =IFERROR(IF(I14="","",MIN(1,MAX(0,(TODAY()-I14)/(J14-I14)))),"") | N14: Pilot tier live; WRP-eligible volume captured | O14: Pricing model | Q14: Awaiting fill-rate stabilisation first | R14: 46180
B15: RT-11 | C15: Centre-visible compliance / credential dashboard | D15: Real-time credential expiry tracking visible to centres. Launch hook: GECKO child-safety training mandatory on portal 1 Jul 2026. | E15: Technology | F15: Raj/Prince | G15: Not Started | H15: P3 | J15: 46295 | K15: =IF(I15="","",IF(G15="Complete",R15-I15,TODAY()-I15)) | L15: =IF(J15="","",IF(G15="Complete","Done",J15-TODAY())) -> 113 | M15: =IFERROR(IF(I15="","",MIN(1,MAX(0,(TODAY()-I15)/(J15-I15)))),"") | N15: Centres can see educator compliance status live | O15: App / Portal | Q15: Tied to GECKO 1 Jul rollout | R15: 46180
B16: RT-13 | C16: Build & maintain Initiative Tracker (this file) | D16: Single source of truth for all initiatives, owners, deadlines, status. Updated weekly; reviewed in Monday check-in. | E16: Governance | F16: Joy | G16: In Progress | H16: P1 | I16: 46179 | J16: 46182 | K16: =IF(I16="","",IF(G16="Complete",R16-I16,TODAY()-I16)) -> 3 | L16: =IF(J16="","",IF(G16="Complete","Done",J16-TODAY())) -> 0 | M16: =IFERROR(IF(I16="","",MIN(1,MAX(0,(TODAY()-I16)/(J16-I16)))),"") -> 1 | N16: All initiatives logged with owner/date/status; updated weekly | O16: This file | Q16: Tracker built; rolling out to managers | R16: 46180
B17: RT-13 | C17: Team Observation | D17: Shadow and observe each function (booking mornings, onboarding calls, reference checks, inbound queue) to understand how work actually happens vs how it's documented. Feeds the structure review and SOP revision with ground truth. | E17: Governance | F17: Joy/Sophia | G17: In Progress | H17: P1 | I17: 46175 | J17: 46200 | K17: =IF(I17="","",IF(G17="Complete",R17-I17,TODAY()-I17)) -> 7 | L17: =IF(J17="","",IF(G17="Complete","Done",J17-TODAY())) -> 18 | M17: =IFERROR(IF(I17="","",MIN(1,MAX(0,(TODAY()-I17)/(J17-I17)))),"") -> 0.28 | N17: Each function (booking, onboarding, references, inbound queue) observed and documented; written ground-truth notes feed the structure review and SOP revision | O17: Direct observation / shadowing notes | P17: Requires time with offshore team across their working hours | Q17: Observation schedule being set with managers | R17: 46180
B18: RT-14 | C18: New Team Structure & Clear Responsibilities | D18: Map the existing team as-is — who does what across booking, onboarding, QA, operations, and the offshore Philippines consultants. Surface overlaps, gaps, and the fact that Liam is stretched across strategic, operational, and tactical work. Baseline for designing the new structure. Design the target operating model — defined roles, a layer between Liam and the managers (senior ops manager), local SA workforce partner, and clear split between transactional (offshore) vs relationship (on-ground) work. Output: org chart + RACI so every role is well-defined. | E18: People & Org | F18: Sophia | G18: Not Started | H18: P1 | K18: =IF(I18="","",IF(G18="Complete",R18-I18,TODAY()-I18)) | L18: =IF(J18="","",IF(G18="Complete","Done",J18-TODAY())) | M18: =IFERROR(IF(I18="","",MIN(1,MAX(0,(TODAY()-I18)/(J18-I18)))),"") | N18: Approved org chart + RACI delivered; every role has defined responsibilities; senior ops layer and local SA workforce partner positions scoped | O18: Current Team Structure Review + Team Observation outputs | P18: Depends on structure review and observation completing first; needs Liam sign-off | Q18: Awaiting baseline from structure review | R18: 46180
B19: RT-15 | C19: ClickUp Replacement OR Alternative Ways to better organise it | D19: Evaluate whether ClickUp is fit for purpose or should be replaced/reconfigured. Assess against team workflows (task tracking, onboarding pipeline, app-issue escalations to Prince). Recommend either an optimised ClickUp setup or an alternative. | E19: Technology | F19: Joy | G19: Not Started | H19: P3 | K19: =IF(I19="","",IF(G19="Complete",R19-I19,TODAY()-I19)) | L19: =IF(J19="","",IF(G19="Complete","Done",J19-TODAY())) | M19: =IFERROR(IF(I19="","",MIN(1,MAX(0,(TODAY()-I19)/(J19-I19)))),"") | N19: Documented recommendation (optimise ClickUp vs replace) with cost-benefit; decision made and rollout plan agreed | O19: Team workflows / ClickUp usage / consultant feedback | P19: Lower priority than fill-rate fixes; avoid disruption during peak season | Q19: Not started — scoping after SA stabilises | R19: 46180
B20: RT-16 | C20: SOP Review and Revision | D20: Audit existing SOPs and call flows (vetting call, reference checks, video interview, booking management) for gaps and inconsistencies. Rewrite to a single standard so expectations are clear and repeatable — directly supports onboarding rebuild and quality. | E20: Governance | F20: Joy | G20: In Progress | H20: P1 | I20: 46180 | K20: =IF(I20="","",IF(G20="Complete",R20-I20,TODAY()-I20)) -> 2 | L20: =IF(J20="","",IF(G20="Complete","Done",J20-TODAY())) | M20: =IFERROR(IF(I20="","",MIN(1,MAX(0,(TODAY()-I20)/(J20-I20)))),"") -> 0 | N20: All core SOPs/call flows (vetting, references, video interview, booking) audited and rewritten to one standard; team trained on new versions | O20: Existing SOPs / call recordings / Team Observation | P20: Depends on Team Observation findings; coordinate with onboarding rebuild (RT-07) | Q20: Pending observation completion | R20: 46180
B21: RT-17 | C21: Child Safety Training as mandatory for educators | D21: Since this is going to be mandatory in August for educators to work in childcare, we need to reach out to educators to complete this and also we'll need to make this mandatory in our system for July | E21: Supply / Educators | F21: Sophia | G21: Not Started | H21: P1 | I21: 46183
B22: RT-18 | C22: Consultant Call Quality Audit & Performance Assessment | D22: Listen to all consultant onboarding/vetting calls. Rate each consultant on commercial awareness, rapport-building, urgency creation, and call structure. Output: retain / coach with timeline / replace recommendation per team member. | E22: People & Org | F22: Joy/Sophia | G22: Not Started | H22: P1 | I22: 46188 | J22: 46200 | K22: =IF(I22="","",IF(G22="Complete",R22-I22,TODAY()-I22)) -> -6 | L22: =IF(J22="","",IF(G22="Complete","Done",J22-TODAY())) -> 18 | M22: =IFERROR(IF(I22="","",MIN(1,MAX(0,(TODAY()-I22)/(J22-I22)))),"") -> 0 | N22: Assessment matrix complete; at least one coaching plan or replacement action initiated | O22: Adelaide_Visit_Plan_Jun2026 file; Consultant Call QA file | R22: 46181
B23: RT-19 | C23: Lead Generation Framework via Onboarding Calls | D23: Build structured question framework for vetting/onboarding calls that extracts centre intelligence (centre name, address, agency usage frequency, contact name/role/email) and routes it as a qualified lead into JobAdder CRM. Directly supports Liam's centre visit pipeline. | E23: Onboarding (Applicant) | F23: Joy/Sophia | G23: Not Started | H23: P1 | K23: =IF(I23="","",IF(G23="Complete",R23-I23,TODAY()-I23)) | L23: =IF(J23="","",IF(G23="Complete","Done",J23-TODAY())) | M23: =IFERROR(IF(I23="","",MIN(1,MAX(0,(TODAY()-I23)/(J23-I23)))),"") | N23: Leads flowing from onboarding calls into JobAdder; Liam has a prioritised centre visit list sourced from educator intel | O23: JobAdder CRM, onboarding call logs | P23: Requires updated call script + consultant training before rollout | R23: 46181
B24: RT-20 | C24: WRP Extra Toggle + Pay Rate Profitability Model | D24: Joy to build per-centre profitability model showing cost impact of enabling "base + extra + WRP" toggle for WRP-enrolled SA centres. Once validated, Liam enables in system to make Raw Talent the highest-paying option for experienced agency educators and reduce cancellations. | E24: Operations | F24: Joy | G24: Not Started | H24: P1 | K24: =IF(I24="","",IF(G24="Complete",R24-I24,TODAY()-I24)) | L24: =IF(J24="","",IF(G24="Complete","Done",J24-TODAY())) | M24: =IFERROR(IF(I24="","",MIN(1,MAX(0,(TODAY()-I24)/(J24-I24)))),"") | N24: Model built; toggle enabled at minimum for top 4 worst-fill SA centres; cancellation rate measurably drops | O24: SA Educator Engagement Report, Edge charge rate data, WRP enrolled centre list | P24: Needs Edge charge rates per centre before model can be finalised; links to RT-02 | R24: 46181
B25: RT-21 | C25: Educator Referral Program | D25: Design and launch a referral incentive program where current educators refer new educators to Raw Talent. Liam confirmed this should exist but currently doesn't. Define reward structure, eligibility criteria, and how it's communicated in onboarding calls. | E25: Supply / Educators | F25: Joy/Sophia | G25: Not Started | H25: P2 | K25: =IF(I25="","",IF(G25="Complete",R25-I25,TODAY()-I25)) | L25: =IF(J25="","",IF(G25="Complete","Done",J25-TODAY())) | M25: =IFERROR(IF(I25="","",MIN(1,MAX(0,(TODAY()-I25)/(J25-I25)))),"") | N25: Program live; at least 10 referrals generated within first 4 weeks | O25: App registration data | P25: Needs Liam sign-off on reward structure/budget before launch | R25: 46181
B26: RT-22 | C26: Cross-Train All Consultants: Onboarding + Inbound | D26: All consultants to be trained to handle both outbound onboarding calls and inbound calls from candidates/clients. Currently inbound calls are bottlenecked because not all team members are confident taking them. Ties to team quality review (RT-18). | E26: People & Org | F26: Joy/Sophia | G26: Not Started | H26: P2 | K26: =IF(I26="","",IF(G26="Complete",R26-I26,TODAY()-I26)) | L26: =IF(J26="","",IF(G26="Complete","Done",J26-TODAY())) | M26: =IFERROR(IF(I26="","",MIN(1,MAX(0,(TODAY()-I26)/(J26-I26)))),"") | N26: Every active consultant can independently manage an inbound call; zero dropped inbound calls due to team capacity | O26: Call handling logs, ClickUp task completion | P26: Dependent on RT-18 outcome (need to know who stays first); SOP revision (RT-16) should precede training | R26: 46181
B27: RT-23 | C27: Afternoon Leadership Coverage (Post-Jane Transition) | D27: Jane is stepping back from the afternoon space. Sophia to take on leadership in the PM window. Joy to coordinate with Sophia on AM/PM coverage split to ensure management presence across both windows. This will start after team structure review. | E27: People & Org | F27: Joy/Sophia | G27: Not Started | H27: P1 | K27: =IF(I27="","",IF(G27="Complete",R27-I27,TODAY()-I27)) | L27: =IF(J27="","",IF(G27="Complete","Done",J27-TODAY())) | M27: =IFERROR(IF(I27="","",MIN(1,MAX(0,(TODAY()-I27)/(J27-I27)))),"") | N27: AM/PM coverage schedule confirmed and operational; no leadership gap in afternoon window | O27: Team schedule / roster | P27: Liam to formally communicate Jane's reduced scope to the team | R27: 46181
B28: RT-24 | C28: Identifying Active Student in VIC | D28: We'll identify Active Student in VIC by pulling a report from IT, and we'll reach out to them to clarify their course progress. - If completed - Ask educator to provide completion letter & update the qualification details - If still in progress - Put educator to the centre banned list (Happy Hippo Brunswick & Wattletree Malvern) | E28: Supply / Educators | F28: Sophia | G28: Not Started | H28: P1 | K28: =IF(I28="","",IF(G28="Complete",R28-I28,TODAY()-I28)) | L28: =IF(J28="","",IF(G28="Complete","Done",J28-TODAY())) | M28: =IFERROR(IF(I28="","",MIN(1,MAX(0,(TODAY()-I28)/(J28-I28)))),"")
B29: RT-25 | C29: Automated Last-minute Shift Confirmation | D29: Work with the IT team to develop an automated Shift Confirmation system. The system would: - Ask educators to reconfirm their shifts - Display our expectations/reminders before the shift (e.g. Be 10 minutes early, bring Sunhat and WWCC, Uniform standard, and encouragement for engagement) - Notify our team once the educator confirms - Show a confirmation indicator on the booking status We should have: - One confirmation flow for regular educators - Another confirmation flow for educators attending their first shift with us | E29: Technology | F29: Joy/Sophia | G29: Not Started | H29: P2 | K29: =IF(I29="","",IF(G29="Complete",R29-I29,TODAY()-I29)) | L29: =IF(J29="","",IF(G29="Complete","Done",J29-TODAY())) | M29: =IFERROR(IF(I29="","",MIN(1,MAX(0,(TODAY()-I29)/(J29-I29)))),"")
B30: RT-26 | C30: New Onboarding Approach | D30: Jane is currently working on a new onboarding approach from start to finish and has created a presentation outlining the proposed process improvements. The goal is to: - Streamline onboarding workflows - Improve candidate experience - Reduce delays and manual follow-ups - Create a more structured onboarding journey | E30: Onboarding (Applicant) | F30: Jane | G30: Not Started | H30: P2 | K30: =IF(I30="","",IF(G30="Complete",R30-I30,TODAY()-I30)) | L30: =IF(J30="","",IF(G30="Complete","Done",J30-TODAY())) | M30: =IFERROR(IF(I30="","",MIN(1,MAX(0,(TODAY()-I30)/(J30-I30)))),"")
B31: RT-27 | C31: Follow-Up Email Templates | D31: Create standardised email templates for the team to use when following up on incorrect or missing documents. This would: - Reduce the amount of manual calling required - Improve communication consistency - Save time for the onboarding team - Allow candidates to clearly understand what corrections are needed | E31: Onboarding (Applicant) | G31: Not Started | H31: P2 | K31: =IF(I31="","",IF(G31="Complete",R31-I31,TODAY()-I31)) | L31: =IF(J31="","",IF(G31="Complete","Done",J31-TODAY())) | M31: =IFERROR(IF(I31="","",MIN(1,MAX(0,(TODAY()-I31)/(J31-I31)))),"")
B32: RT-28 | C32: New Educator Dashboard | D32: Develop a dashboard for active educators where they can easily view: - Number of assigned shifts - Accepted shifts - Completed shifts - Cancelled shifts This would improve educator visibility, engagement, and accountability while reducing inbound enquiries regarding booking history and schedules. | E32: Technology | G32: Not Started | H32: P3 | K32: =IF(I32="","",IF(G32="Complete",R32-I32,TODAY()-I32)) | L32: =IF(J32="","",IF(G32="Complete","Done",J32-TODAY())) | M32: =IFERROR(IF(I32="","",MIN(1,MAX(0,(TODAY()-I32)/(J32-I32)))),"")
B33: RT-29 | C33: New Reference Check Form | D33: Create a new reference check form | E33: Onboarding (Applicant) | F33: Liam | G33: In Progress | H33: P1 | I33: 46181 | J33: 46185 | K33: =IF(I33="","",IF(G33="Complete",R33-I33,TODAY()-I33)) -> 1 | L33: =IF(J33="","",IF(G33="Complete","Done",J33-TODAY())) -> 3 | M33: =IFERROR(IF(I33="","",MIN(1,MAX(0,(TODAY()-I33)/(J33-I33)))),"") -> 0.25
K34: =IF(I34="","",IF(G34="Complete",R34-I34,TODAY()-I34)) | L34: =IF(J34="","",IF(G34="Complete","Done",J34-TODAY())) | M34: =IFERROR(IF(I34="","",MIN(1,MAX(0,(TODAY()-I34)/(J34-I34)))),"")
K35: =IF(I35="","",IF(G35="Complete",R35-I35,TODAY()-I35)) | L35: =IF(J35="","",IF(G35="Complete","Done",J35-TODAY())) | M35: =IFERROR(IF(I35="","",MIN(1,MAX(0,(TODAY()-I35)/(J35-I35)))),"")
K36: =IF(I36="","",IF(G36="Complete",R36-I36,TODAY()-I36)) | L36: =IF(J36="","",IF(G36="Complete","Done",J36-TODAY())) | M36: =IFERROR(IF(I36="","",MIN(1,MAX(0,(TODAY()-I36)/(J36-I36)))),"")
K37: =IF(I37="","",IF(G37="Complete",R37-I37,TODAY()-I37)) | L37: =IF(J37="","",IF(G37="Complete","Done",J37-TODAY())) | M37: =IFERROR(IF(I37="","",MIN(1,MAX(0,(TODAY()-I37)/(J37-I37)))),"")
K39: =IF(I39="","",IF(G39="Complete",R39-I39,TODAY()-I39)) | L39: =IF(J39="","",IF(G39="Complete","Done",J39-TODAY())) | M39: =IFERROR(IF(I39="","",MIN(1,MAX(0,(TODAY()-I39)/(J39-I39)))),"")
K40: =IF(I40="","",IF(G40="Complete",R40-I40,TODAY()-I40)) | L40: =IF(J40="","",IF(G40="Complete","Done",J40-TODAY())) | M40: =IFERROR(IF(I40="","",MIN(1,MAX(0,(TODAY()-I40)/(J40-I40)))),"")
K41: =IF(I41="","",IF(G41="Complete",R41-I41,TODAY()-I41)) | L41: =IF(J41="","",IF(G41="Complete","Done",J41-TODAY())) | M41: =IFERROR(IF(I41="","",MIN(1,MAX(0,(TODAY()-I41)/(J41-I41)))),"")
K42: =IF(I42="","",IF(G42="Complete",R42-I42,TODAY()-I42)) | L42: =IF(J42="","",IF(G42="Complete","Done",J42-TODAY())) | M42: =IFERROR(IF(I42="","",MIN(1,MAX(0,(TODAY()-I42)/(J42-I42)))),"")
...

Sheet Weekly Check-in
B2: RawTalent · Weekly Check-in (Mondays · 20–30 min)
B4: 1. Dashboard review
B5: How many Blocked / At Risk? Any overdue? % complete trend vs last week?
B7: 2. P1 walk-through
B8: Each P1 owner: 30-sec update — status, blocker, next action. Unblock live.
B10: 3. SA fill-rate check
B11: Top centres (Royal Park, Brahma Lodge, Virginia) — are we trending to 90%?
B13: 4. P2 spot check
B14: Anything not moved in 2 weeks? Keep / escalate / hold.
B16: 5. New projects
B17: Log anything raised last week — assign owner, target date, metric TODAY.
B19: 6. Wins
... B23: Everyone updates their rows in Initiatives before EOD Monday.

Sheet How to Use
B2: RawTalent · How to Use This Tracker
B4: PURPOSE
B5: One source of truth for every initiative — who owns it, when it is due, how far along it is, and how we know it worked.
B7: OPENING IN GOOGLE SHEETS
B8: Upload this .xlsx to Google Drive, right-click > Open with > Google Sheets. Dropdowns, colours, formulas and charts all carry over.
B10: THE TABS
B11: Dashboard — live KPI cards + charts. Do not edit; it reads from Initiatives.
B12: Projects — the main tracker. Add one row per initiative. Update weekly.
B13: Weekly Check-in — run this agenda every Monday.
B14: How to Use — this page.
B16: FILLING IT IN
B17: Status, Priority, Category and Owner are dropdowns — just pick.
... B28: If it has no owner and no target date, it is not an initiative — it is a wish. Do not log it until both exist.
